Traceback (most recent call last):
  File "/usr/local/lib/python3.8/runpy.py", line 194, in _run_module_as_main
    return _run_code(code, main_globals, None,
  File "/usr/local/lib/python3.8/runpy.py", line 87, in _run_code
    exec(code, run_globals)
  File "/usr/local/lib/python3.8/http/server.py", line 1294, in <module>
    test(
  File "/usr/local/lib/python3.8/http/server.py", line 1249, in test
    with ServerClass(addr, HandlerClass) as httpd:
  File "/usr/local/lib/python3.8/socketserver.py", line 452, in __init__
    self.server_bind()
  File "/usr/local/lib/python3.8/http/server.py", line 1292, in server_bind
    return super().server_bind()
  File "/usr/local/lib/python3.8/http/server.py", line 138, in server_bind
    socketserver.TCPServer.server_bind(self)
  File "/usr/local/lib/python3.8/socketserver.py", line 466, in server_bind
    self.socket.bind(self.server_address)
OSError: [Errno 98] Address already in use
 * Environment: development
 * Debug mode: on
 * Running on http://127.0.0.1:5000/ (Press CTRL+C to quit)
 * Restarting with stat
 * Debugger is active!
 * Debugger PIN: 364-016-714
127.0.0.1 - - [25/Dec/2021 22:36:19] "GET / HTTP/1.1" 200 -
127.0.0.1 - - [25/Dec/2021 22:36:19] "[36mGET /static/css/main.css HTTP/1.1[0m" 304 -
127.0.0.1 - - [25/Dec/2021 22:36:19] "[36mGET /static/js/extention/choices.js HTTP/1.1[0m" 304 -
127.0.0.1 - - [25/Dec/2021 22:36:25] "[32mGET /github HTTP/1.1[0m" 302 -
127.0.0.1 - - [25/Dec/2021 22:36:26] "[32mGET /github/authorized?code=3203aaaa5b817f9259f3&state=Cs08Lc6rxu3fgL6n07M036w0yK9RVF HTTP/1.1[0m" 302 -
127.0.0.1 - - [25/Dec/2021 22:36:27] "GET / HTTP/1.1" 200 -
